Workbook
Name list: '[1]End user price list 2015'!$A$2:$E$4952

Sheet КСС
A1: № | B1: ЕЛЕКТРИЧЕСКИ ТАБЛА | C1: МЯРКА | D1: К-ВО | E1: ЕД.ЦЕНА ДОСТАВКА | F1: СУМА
A2: 1 | B2: =Табла!C1 -> ГЕТ А секция 1 | C2: бр. | D2: =Табла!F1 -> 1 | E2: =Табла!F19 -> 861.21 | F2: =D2*E2 -> 861.21
A3: 2 | B3: =Табла!C21 -> ГЕТ А секция 2 | C3: бр. | D3: =Табла!F21 -> 1 | E3: =Табла!F37 -> 782.81 | F3: =D3*E3 -> 782.81
A4: 3 | B4: =Табла!C39 -> ГЕТ Б секция 1 | C4: бр. | D4: =Табла!F39 -> 1 | E4: =Табла!F57 -> 837.88 | F4: =D4*E4 -> 837.88
A5: 4 | B5: =Табла!C59 -> ГЕТ Б секция 2 | C5: бр. | D5: =Табла!F59 -> 1 | E5: =Табла!F75 -> 775.75 | F5: =D5*E5 -> 775.75
A6: 5 | B6: =Табла!C77 -> 0 | C6: бр. | D6: =Табла!F77 -> 1 | E6: =Табла!F109 -> 0 | F6: =D6*E6 -> 0
A7: 6 | B7: =Табла!C111 -> 0 | C7: бр. | D7: =Табла!F111 -> 1 | E7: =Табла!F144 -> 0 | F7: =D7*E7 -> 0
A8: 7 | B8: =Табла!C146 -> 0 | C8: бр. | D8: =Табла!F146 -> 1 | E8: =Табла!F180 -> 0 | F8: =D8*E8 -> 0
A9: 8 | B9: =Табла!C182 -> 0 | C9: бр. | D9: =Табла!F182 -> 1 | E9: =Табла!F215 -> 0 | F9: =D9*E9 -> 0
A10: 9 | B10: =Табла!C217 -> 0 | C10: бр. | D10: =Табла!F217 -> 1 | E10: =Табла!F253 -> 0 | F10: =D10*E10 -> 0
A11: 10 | B11: =Табла!C255 -> 0 | C11: бр. | D11: =Табла!F255 -> 1 | E11: =Табла!F288 -> 0 | F11: =D11*E11 -> 0
A12: 11 | B12: =Табла!C290 -> 0 | C12: бр. | D12: =Табла!F290 -> 1 | E12: =Табла!F323 -> 0 | F12: =D12*E12 -> 0
A13: 12 | B13: =Табла!C325 -> 0 | C13: бр. | D13: =Табла!F325 -> 1 | E13: =Табла!F358 -> 0 | F13: =D13*E13 -> 0
A14: 13 | B14: =Табла!C360 -> 0 | C14: бр. | D14: =Табла!F360 -> 1 | E14: =Табла!F393 -> 0 | F14: =D14*E14 -> 0
A15: 14 | B15: =Табла!C395 -> 0 | C15: бр. | D15: =Табла!F395 -> 1 | E15: =Табла!F428 -> 0 | F15: =D15*E15 -> 0
A16: 15 | B16: =Табла!C430 -> 0 | C16: бр. | D16: =Табла!F430 -> 1 | E16: =Табла!F463 -> 0 | F16: =D16*E16 -> 0
A17: 16 | B17: =Табла!C465 -> 0 | C17: бр. | D17: =Табла!F465 -> 1 | E17: =Табла!F498 -> 0 | F17: =D17*E17 -> 0
A18: 17 | B18: =Табла!C500 -> 0 | C18: бр. | D18: =Табла!F500 -> 1 | E18: =Табла!F533 -> 0 | F18: =D18*E18 -> 0
A19: 18 | B19: =Табла!C535 -> 0 | C19: бр. | D19: =Табла!F535 -> 1 | E19: =Табла!F568 -> 0 | F19: =D19*E19 -> 0
A20: 19 | B20: =Табла!C570 -> 0 | C20: бр. | D20: =Табла!F570 -> 1 | E20: =Табла!F603 -> 0 | F20: =D20*E20 -> 0
A21: 20 | B21: =Табла!C605 -> 0 | C21: бр. | D21: =Табла!F605 -> 1 | E21: =Табла!F638 -> 0 | F21: =D21*E21 -> 0
A22: 21 | B22: =Табла!C640 -> 0 | C22: бр. | D22: =Табла!F640 -> 1 | E22: =Табла!F673 -> 0 | F22: =D22*E22 -> 0
A23: 22 | B23: =Табла!C675 -> 0 | C23: бр. | D23: =Табла!F675 -> 1 | E23: =Табла!F708 -> 0 | F23: =D23*E23 -> 0
A24: 23 | B24: =Табла!C710 -> 0 | C24: бр. | D24: =Табла!F710 -> 1 | E24: =Табла!F743 -> 0 | F24: =D24*E24 -> 0
A25: 24 | B25: =Табла!C745 -> 0 | C25: бр. | D25: =Табла!F745 -> 1 | E25: =Табла!F778 -> 0 | F25: =D25*E25 -> 0
A26: 25 | B26: =Табла!C780 -> 0 | C26: бр. | D26: =Табла!F780 -> 1 | E26: =Табла!F813 -> 0 | F26: =D26*E26 -> 0
A27: 26 | B27: =Табла!C815 -> 0 | C27: бр. | D27: =Табла!F815 -> 1 | E27: =Табла!F848 -> 0 | F27: =D27*E27 -> 0
A28: 27 | B28: =Табла!C850 -> 0 | C28: бр. | D28: =Табла!F850 -> 1 | E28: =Табла!F883 -> 0 | F28: =D28*E28 -> 0
A29: 28 | B29: =Табла!C885 -> 0 | C29: бр. | D29: =Табла!F885 -> 1 | E29: =Табла!F918 -> 0 | F29: =D29*E29 -> 0
A30: 29 | B30: =Табла!C920 -> 0 | C30: бр. | D30: =Табла!F920 -> 1 | E30: =Табла!F953 -> 0 | F30: =D30*E30 -> 0
A31: 30 | B31: =Табла!C955 -> 0 | C31: бр. | D31: =Табла!F955 -> 1 | E31: =Табла!F988 -> 0 | F31: =D31*E31 -> 0
A32: 31 | B32: =Табла!C990 -> 0 | C32: бр. | D32: =Табла!F990 -> 1 | E32: =Табла!F1023 -> 0 | F32: =D32*E32 -> 0
A33: 32 | B33: =Табла!C1025 -> 0 | C33: бр. | D33: =Табла!F1025 -> 1 | E33: =Табла!F1058 -> 0 | F33: =D33*E33 -> 0
A34: 33 | B34: =Табла!C1060 -> 0 | C34: бр. | D34: =Табла!F1060 -> 1 | E34: =Табла!F1093 -> 0 | F34: =D34*E34 -> 0
A35: 34 | B35: =Табла!C1095 -> 0 | C35: бр. | D35: =Табла!F1095 -> 1 | E35: =Табла!F1128 -> 0 | F35: =D35*E35 -> 0
A36: 35 | B36: =Табла!C1130 -> 0 | C36: бр. | D36: =Табла!F1130 -> 1 | E36: =Табла!F1163 -> 0 | F36: =D36*E36 -> 0
A37: 36 | B37: =Табла!C1165 -> 0 | C37: бр. | D37: =Табла!F1165 -> 1 | E37: =Табла!F1198 -> 0 | F37: =D37*E37 -> 0
A38: 37 | B38: =Табла!C1200 -> 0 | C38: бр. | D38: =Табла!F1200 -> 1 | E38: =Табла!F1233 -> 0 | F38: =D38*E38 -> 0
A39: 38 | B39: =Табла!C1235 -> 0 | C39: бр. | D39: =Табла!F1235 -> 1 | E39: =Табла!F1268 -> 0 | F39: =D39*E39 -> 0
A40: 39 | B40: =Табла!C1270 -> 0 | C40: бр. | D40: =Табла!F1270 -> 1 | E40: =Табла!F1303 -> 0 | F40: =D40*E40 -> 0
...

Sheet Табла
A1: 1 | B1: Табло: | C1: ГЕТ А секция 1 | E1: Количество: | F1: 1
A2: № | B2: Код | C2: Наименование на стоките и услугите | D2: К-во | E2: Ед. цена | F2: Стойност
A3: 1 | B3: 004671073 | C3: Автоматичен прекъсвач лят корпус EB2 250/3L 250A 3p | D3: 1 | E3: 246.46 | F3: =D3*E3 -> 246.46
A4: 2 | B4: 002423314 | C4: Товаров прекъсвач SV 363 3p 63A | D4: 2 | E4: 21.67 | F4: =D4*E4 -> 43.34
A5: 3 | B5: 002423114 | C5: Товаров прекъсвач SV 163 1p 63A | D5: 37 | E5: 7.44 | F5: =D5*E5 -> 275.28
A6: 4 | B6: 002423314 | C6: Товаров прекъсвач SV 363 3p 63A | D6: 2 | E6: 21.67 | F6: =D6*E6 -> 43.34
A7: 5 | B7: 001900336 | C7: Миниатюрен автоматичен прекъсвач ETIMAT P6 3p C63 | D7: 1 | E7: 26.68 | F7: =D7*E7 -> 26.68
A8: 6 | B8: 001900334 | C8: Миниатюрен автоматичен прекъсвач ETIMAT P6 3p C40 | D8: 1 | E8: 15.77 | F8: =D8*E8 -> 15.77
A9: 7 | B9: 001900030 | C9: Миниатюрен автоматичен прекъсвач ETIMAT P6 1p C16 | D9: 12 | E9: 3.57 | F9: =D9*E9 -> 42.84
A10: 8 | B10: 001900034 | C10: Миниатюрен автоматичен прекъсвач ETIMAT P6 1p C40 | D10: 5 | E10: 4.7 | F10: =D10*E10 -> 23.5
A11: 9 | B11: 001900035 | C11: Миниатюрен автоматичен прекъсвач ETIMAT P6 1p C50 | D11: 20 | E11: 7.2 | F11: =D11*E11 -> 144
A12: 10 | F12: =D12*E12 -> 0
E13: Сума за ел. компоненти | F13: =SUM(F3:F12) -> 861.21
A15: 1 | C15: Метално табло | D15: 1 | F15: =D15*E15 -> 0
A16: 2 | C16: Консумативи | D16: 1 | F16: =D16*E16 -> 0
A17: 3 | C17: Изработка | D17: 1 | F17: =D17*E17 -> 0
E18: Сума за асемблиране | F18: =SUM(F15:F17) -> 0
E19: Общо Цена без ДДС: | F19: =F18+F13 -> 861.21
A21: 2 | B21: Табло: | C21: ГЕТ А секция 2 | E21: Количество: | F21: 1
A22: № | B22: Код | C22: Наименование на стоките и услугите | D22: К-во | E22: Ед. цена | F22: Стойност
A23: 1 | B23: 004671073 | C23: Автоматичен прекъсвач лят корпус EB2 250/3L 250A 3p | D23: 1 | E23: 246.46 | F23: =D23*E23 -> 246.46
A24: 2 | B24: 002423114 | C24: Товаров прекъсвач SV 163 1p 63A | D24: 40 | E24: 7.44 | F24: =D24*E24 -> 297.6
A25: 3 | B25: 002423314 | C25: Товаров прекъсвач SV 363 3p 63A | D25: 2 | E25: 21.67 | F25: =D25*E25 -> 43.34
A26: 4 | B26: 001900030 | C26: Миниатюрен автоматичен прекъсвач ETIMAT P6 1p C16 | D26: 15 | E26: 3.57 | F26: =D26*E26 -> 53.55
A27: 5 | B27: 001900034 | C27: Миниатюрен автоматичен прекъсвач ETIMAT P6 1p C40 | D27: 4 | E27: 4.7 | F27: =D27*E27 -> 18.8
A28: 6 | B28: 001900035 | C28: Миниатюрен автоматичен прекъсвач ETIMAT P6 1p C50 | D28: 15 | E28: 7.2 | F28: =D28*E28 -> 108
A29: 7 | B29: 001900036 | C29: Миниатюрен автоматичен прекъсвач ETIMAT P6 1p C63 | D29: 2 | E29: 7.53 | F29: =D29*E29 -> 15.06
A30: 8 | F30: =D30*E30 -> 0
E31: Сума за ел. компоненти | F31: =SUM(F23:F30) -> 782.81
A33: 1 | C33: Метално табло | D33: 1 | F33: =D33*E33 -> 0
A34: 2 | C34: Консумативи | D34: 1 | F34: =D34*E34 -> 0
A35: 3 | C35: Изработка | D35: 1 | F35: =D35*E35 -> 0
E36: Сума за асемблиране | F36: =SUM(F33:F35) -> 0
E37: Общо Цена без ДДС: | F37: =F36+F31 -> 782.81
A39: 3 | B39: Табло: | C39: ГЕТ Б секция 1 | E39: Количество: | F39: 1
A40: № | B40: Код | C40: Наименование на стоките и услугите | D40: К-во | E40: Ед. цена | F40: Стойност
A41: 1 | B41: 004671073 | C41: Автоматичен прекъсвач лят корпус EB2 250/3L 250A 3p | D41: 1 | E41: 246.46 | F41: =D41*E41 -> 246.46
A42: 2 | B42: 002423314 | C42: Товаров прекъсвач SV 363 3p 63A | D42: 2 | E42: 21.67 | F42: =D42*E42 -> 43.34
A43: 3 | B43: 002423114 | C43: Товаров прекъсвач SV 163 1p 63A | D43: 34 | E43: 7.44 | F43: =D43*E43 -> 252.96
A44: 4 | B44: 002423314 | C44: Товаров прекъсвач SV 363 3p 63A | D44: 2 | E44: 21.67 | F44: =D44*E44 -> 43.34
...
